Workbook

Sheet Data
A1: 상품 | B1: 수량 | C1: 단가 | D1: 비고 | F1: 이름 | G1: 점수 | H1: 부서 | J1: 기준점 | K1: 등급 | M1: 내림차순
A2: 사과 | B2: 12 | C2: 1200 | F2: 김민준 | G2: 85 | H2: 영업 | J2: 0 | K2: F | M2: 90
A3: 배 | B3: 7 | C3: 2500 | D3: 할인 | F3: 이서연 | G3: 92 | H3: 개발 | J3: 60 | K3: D | M3: 80
A4: 귤 | B4: 30 | C4: 400 | F4: 박도윤 | G4: 78 | H4: 영업 | J4: 70 | K4: C | M4: 70
A5: 포도 | B5: 5 | C5: 3200 | D5: 할인 | F5: 최하은 | H5: 개발 | J5: 80 | K5: B | M5: 60
A6: 감 | B6: 18 | C6: 900 | D6: 품절 | F6: 정시우 | G6: 64 | H6: 인사 | J6: 90 | K6: A | M6: 0
F7: 한지아 | G7: 결석 | H7: 영업

Sheet D4_Exponent
A1: 입력1 | B1: 입력2 | C1: 수식 | D1: 검증 내용 | E1: 비교 방식
C2: =1E+3 | D2: 양의 지수(부호 포함) | E2: 값(원본수식)
C3: =1E3 | D3: 양의 지수(부호 없음) | E3: 값(원본수식)
C4: =2.5E-1 | D4: 음의 지수 | E4: 값(원본수식)
C5: =1.5E2 | D5: 대문자 E, 소수 가수 | E5: 값(원본수식)
C6: =1.5e2 | D6: 소문자 e | E6: 값(원본수식)
A7: 2 | C7: =A7*1E+3 | D7: 셀 참조와 지수 표기 곱 | E7: 값(원본수식)
C8: =1E+3+1E-3 | D8: 지수 표기 두 개 | E8: 값(원본수식)
C9: ="x"&1E+3 | D9: 문자열 연결 안의 지수 표기 | E9: 값(원본수식)

Sheet D5_Cycle
A1: 입력1 | B1: 입력2 | C1: 수식 | D1: 검증 내용 | E1: 비교 방식
C2: =C2+1 | D2: 자기 자신을 참조 | E2: Excel만
C3: =C4 | D3: 두 셀이 서로 참조(1) | E3: Excel만
C4: =C3+1 | D4: 두 셀이 서로 참조(2) | E4: Excel만
C5: =SUM(C5:C6) | D5: 범위가 자기 자신을 포함 | E5: Excel만
C6: =IFERROR(C6,"대체") | D6: 순환 참조를 IFERROR로 감싼 셀 | E6: Excel만

Sheet D6_NumToText
A1: 입력1 | B1: 입력2 | C1: 수식 | D1: 검증 내용 | E1: 비교 방식
C2: ="x"&(0.1+0.2) | D2: & : 0.30000000000000004 | E2: 값
C3: =CONCATENATE("x",0.1+0.2) | D3: CONCATENATE | E3: 값
C4: =_xlfn.CONCAT("x",0.1+0.2) | D4: CONCAT (어댑터가 15자리 규칙 적용) | E4: 값
C5: ="x"&(1/3) | D5: & : 순환소수 | E5: 값
C6: ="x"&(2/3) | D6: & : 반올림 방향이 바뀌는 순환소수 | E6: 값
C7: ="x"&(1/7) | D7: & : 15자리 경계 | E7: 값
C8: ="x"&1234567890123456 | D8: & : 16자리 정수 | E8: 값
C9: ="x"&123456789012345678 | D9: & : 18자리 정수(과학 표기로 바뀜) | E9: 값
C10: ="x"&(10^15) | D10: & : 1E+15 | E10: 값
C11: ="x"&(10^20) | D11: & : 1E+20 | E11: 값
C12: ="x"&(1/10000000) | D12: & : 1E-07 | E12: 값
C13: ="x"&0.000123 | D13: & : 0.000123 | E13: 값
C14: ="x"&-0.5 | D14: & : 음수 | E14: 값
C15: =LEN(0.1+0.2) | D15: LEN 안에서의 변환 | E15: 값
C16: =LEN(1/3) | D16: LEN : 순환소수 | E16: 값
C17: =LEFT(1/3,5) | D17: LEFT : 숫자를 문자열로 | E17: 값
C18: =(0.1+0.2)=0.3 | D18: 15자리 비교(연관 확인) | E18: 값
C19: =_xlfn.TEXTJOIN(",",TRUE,0.1+0.2,1/3) | D19: TEXTJOIN 안에서의 변환 | E19: 값

Sheet D7_IndexZero
A1: 입력1 | B1: 입력2 | C1: 수식 | D1: 검증 내용 | E1: 비교 방식
C2: =SUM(INDEX(Data!B2:C6,0,2)) | D2: 열 전체(단가 열) 합계 | E2: 차이기록
C3: =SUM(INDEX(Data!B2:C6,2,0)) | D3: 행 전체 합계 | E3: 차이기록
C4: =ROWS(INDEX(Data!A2:C6,0,2)) | D4: 열 전체 배열의 행 수 | E4: 차이기록
C5: =COLUMNS(INDEX(Data!A2:C6,2,0)) | D5: 행 전체 배열의 열 수 | E5: 차이기록
C6: =MAX(INDEX(Data!B2:C6,0,1)) | D6: 열 전체 최댓값 | E6: 차이기록
C7: =SUM(INDEX(Data!B2:B6,0)) | D7: 한 열 범위에 행 번호 0 | E7: 차이기록
C8: =SUM(INDEX(Data!B2:C6,0,0)) | D8: 행·열 모두 0 (범위 전체) | E8: 차이기록
C9: =INDEX(Data!A2:A6,-1) | D9: 음수 행 번호 | E9: 차이기록
C10: =INDEX(Data!A2:C6,2,4) | D10: 열 번호 초과 | E10: 차이기록
C11: =INDEX(Data!A2:C6,6,1) | D11: 행 번호 초과 | E11: 차이기록
C12: =INDEX(Data!A2:C6,2,-1) | D12: 음수 열 번호 | E12: 차이기록
C13: =INDEX(Data!A2:C6,2) | D13: 여러 열 범위에 행 번호만 (첫 열) | E13: 차이기록
C14: =INDEX(Data!A2:C2,2) | D14: 한 행 범위에 번호 하나 (열 번호로 사용) | E14: 차이기록

Sheet D8_Unsupported
A1: 입력1 | B1: 입력2 | C1: 수식 | D1: 검증 내용 | E1: 비교 방식
C2: =AVERAGEIFS(Data!G2:G7,Data!H2:H7,"영업") | D2: AVERAGEIFS | E2: 차이기록
C3: =RANK(Data!G3,Data!G2:G7) | D3: RANK 내림차순 | E3: 차이기록
C4: =RANK(Data!G4,Data!G2:G7,1) | D4: RANK 오름차순 | E4: 차이기록
C5: =_xlfn.RANK.EQ(Data!G2,Data!G2:G7) | D5: RANK.EQ | E5: 차이기록
C6: =_xlfn.XMATCH("박도윤",Data!F2:F7) | D6: XMATCH 정확히 일치 | E6: 차이기록
C7: =_xlfn.XMATCH(80,Data!J2:J6,-1) | D7: XMATCH 작거나 같은 값 | E7: 차이기록
C8: =LOOKUP(85,Data!J2:J6,Data!K2:K6) | D8: LOOKUP 벡터 형식(근사 일치) | E8: 차이기록
C9: =INDEX(_xlfn.SORTBY(Data!F2:F7,Data!G2:G7,-1),1) | D9: SORTBY 후 첫 값 | E9: 차이기록
C10: =_xlfn.MODE.SNGL(Data!B2:B6,12) | D10: MODE.SNGL | E10: 차이기록
C11: =MODE(Data!B2:B6,12) | D11: MODE | E11: 차이기록
C12: =OFFSET(Data!A1,1,1) | D12: OFFSET | E12: 차이기록
C13: =INDIRECT("Data!B2") | D13: INDIRECT | E13: 차이기록
C14: =_xlfn.NUMBERVALUE("1.234,5",",",".") | D14: NUMBERVALUE | E14: 차이기록
C15: =_xlfn.TEXTBEFORE("a-b-c","-") | D15: TEXTBEFORE | E15: 차이기록

Sheet ConcatRange
A1: 입력1 | B1: 입력2 | C1: 수식 | D1: 검증 내용 | E1: 비교 방식 | F1: 문자 | G1: 값 | J1: 오류 셀
C2: =_xlfn.CONCAT(Data!A2:A6) | D2: 한 열 범위 | E2: 값 | F2: 가 | G2: 1.5 | J2: =1/0
C3: =_xlfn.CONCAT(Data!B2:C3) | D3: 2차원 범위는 행 우선 (12,1200,7,2500) | E3: 값 | G3: TRUE
C4: =_xlfn.CONCAT(Data!A2:A3,"-",Data!D2:D3) | D4: 빈 셀 건너뜀 (D2는 빈 셀) | E4: 값 | F4: 나 | G4: 0.3
C5: =_xlfn.CONCAT(F2:F4) | D5: 중간 빈 셀 | E5: 값
C6: =_xlfn.CONCAT(G2:G4) | D6: 숫자·논리값·긴 소수 (1.5TRUE0.3) | E6: 값
C7: =_xlfn.CONCAT(F2:G4) | D7: 문자와 숫자가 섞인 2차원 범위 | E7: 값
C8: =_xlfn.CONCAT(Data!A2:A3,Data!A2:A3) | D8: 범위 인수 두 개 | E8: 값
C9: =_xlfn.CONCAT(Data!G2:G7) | D9: 빈 셀·문자 섞인 점수 열 | E9: 값
C10: =_xlfn.CONCAT(TRUE,FALSE) | D10: 논리값 상수 | E10: 값
C11: =_xlfn.CONCAT(TRUE,1.5) | D11: 논리값과 숫자 | E11: 값
C12: =_xlfn.CONCAT(0.1+0.2) | D12: 숫자는 15자리 일반 서식 | E12: 값
C13: =_xlfn.CONCAT(1/3) | D13: 순환소수 | E13: 값
C14: =_xlfn.CONCAT(J2:J3) | D14: 범위 안의 오류 값 전파 | E14: 값
C15: =_xlfn.CONCAT("a",NA()) | D15: 인수의 오류 전파(#N/A) | E15: 값
C16: =_xlfn.CONCAT("a",1/0,NA()) | D16: 여러 오류는 앞의 것 | E16: 값
C17: =_xlfn.CONCAT(Data!D2:D2) | D17: 빈 셀 하나뿐인 범위 (빈 문자열) | E17: 값
C18: =_xlfn.CONCAT("") | D18: 빈 문자열 | E18: 값
C19: =LEN(_xlfn.CONCAT(REPT("a",32767))) | D19: 32,767자는 허용 | E19: 값
C20: =_xlfn.CONCAT(REPT("a",32767),"b") | D20: 32,768자는 #VALUE! | E20: 값
C21: =_xlfn.CONCAT(F2:F4,G2:G4) | D21: 범위 두 개 (각각 펼침) | E21: 값

Sheet Text
A1: 입력1 | B1: 입력2 | C1: 수식 | D1: 검증 내용 | E1: 비교 방식
C2: =LEFT(Data!F2,1) | D2: LEFT 한글 | E2: 값
C3: =LEFT("abc") | D3: LEFT 글자 수 생략 | E3: 값
C4: =LEFT("abc",10) | D4: LEFT 길이 초과 | E4: 값
C5: =LEFT("abc",-1) | D5: LEFT 음수 | E5: 값
C6: =RIGHT("abcdef",2) | D6: RIGHT | E6: 값
C7: =RIGHT("abc") | D7: RIGHT 글자 수 생략 | E7: 값
C8: =MID("abcdef",2,3) | D8: MID | E8: 값
C9: =MID("abc",5,2) | D9: MID 시작 위치 초과 | E9: 값
C10: =MID("abcdef",0,2) | D10: MID 시작 0 | E10: 값
C11: =MID(Data!F2,2,2) | D11: MID 한글 | E11: 값
C12: =LEN("") | D12: LEN 빈 문자열 | E12: 값
C13: =LEN(123.50) | D13: LEN 숫자 | E13: 값
C14: =LEN(Data!G5) | D14: LEN 빈 셀 | E14: 값
C15: =TRIM(" a b ") | D15: TRIM 앞뒤·중간 공백 | E15: 값
C16: =TRIM(CHAR(160)&"a") | D16: TRIM은 줄바꿈 없는 공백(160)을 지우지 않음 | E16: 값
C17: =LEN(TRIM(" a b ")) | D17: TRIM 후 글자 수 | E17: 값
C18: =_xlfn.TEXTJOIN(",",TRUE,Data!F2:F4) | D18: TEXTJOIN 정상 | E18: 값
C19: =_xlfn.TEXTJOIN(",",TRUE,Data!G4:G6) | D19: TEXTJOIN 빈 셀 무시 | E19: 값
C20: =_xlfn.TEXTJOIN(",",FALSE,Data!G4:G6) | D20: TEXTJOIN 빈 셀 포함 | E20: 값
C21: =_xlfn.TEXTJOIN("-",TRUE,Data!F2:F3,Data!H2:H3) | D21: TEXTJOIN 범위 두 개 | E21: 값
C22: =_xlfn.TEXTJOIN(", ",TRUE,"a","","b") | D22: TEXTJOIN 빈 문자열 인수 무시 | E22: 값
C23: =_xlfn.TEXTJOIN(",",FALSE,"a","","b") | D23: TEXTJOIN 빈 문자열 인수 포함 | E23: 값
C24: =_xlfn.TEXTJOIN(",",TRUE,Data!A2:C3) | D24: TEXTJOIN 2차원 범위 | E24: 값
C25: =_xlfn.TEXTJOIN(,TRUE,"a","b") | D25: TEXTJOIN 구분 기호 생략 | E25: 값
C26: =UPPER("hello")&LOWER("WORLD")&PROPER("hello world") | D26: UPPER·LOWER·PROPER | E26: 값
C27: =FIND("b","abcb") | D27: FIND | E27: 값
C28: =FIND("B","abc") | D28: FIND 대소문자 구분 | E28: 값
C29: =SEARCH("B","abc") | D29: SEARCH 대소문자 무시 | E29: 값
C30: =SUBSTITUTE("a-b-c","-","+") | D30: SUBSTITUTE | E30: 값
C31: =REPLACE("abcdef",2,3,"X") | D31: REPLACE | E31: 값
C32: =VALUE("123")+1 | D32: VALUE | E32: 값
C33: =TEXT(1234.5,"#,##0.00") | D33: TEXT 천 단위 구분 (부분 지원 확인) | E33: 값
C34: =TEXT(1234.5,"0.0") | D34: TEXT 소수 한 자리 | E34: 값
C35: =TEXT(0.256,"0%") | D35: TEXT 백분율 | E35: 값
C36: =TEXT(5,"000") | D36: TEXT 앞자리 0 | E36: 값
C37: =TEXT(DATE(2024,3,15),"yyyy-mm-dd") | D37: TEXT 날짜 | E37: 값
C38: =TEXT(DATE(2024,3,15),"yyyy") | D38: TEXT 연도 | E38: 값
C39: =TEXT(DATE(2024,3,15),"m/d") | D39: TEXT 월/일 | E39: 값

Sheet DateTime
A1: 입력1 | B1: 입력2 | C1: 수식 | D1: 검증 내용 | E1: 비교 방식
C2: =TODAY()-INT(NOW()) | D2: TODAY와 NOW의 날짜 부분은 같다 (0) | E2: 값
C3: =NOW()-TODAY()<1 | D3: NOW의 시간 부분은 1 미만 (TRUE) | E3: 값
C4: =ISNUMBER(TODAY()) | D4: TODAY는 숫자 | E4: 값
C5: =TODAY()>DATE(2024,1,1) | D5: TODAY는 2024년 이후 | E5: 값
C6: =TIME(13,30,0) | D6: TIME | E6: 값
C7: =TIME(25,0,0) | D7: TIME 24시간 넘김 (24시간 나머지) | E7: 값
C8: =TIME(0,90,0) | D8: TIME 분 넘김 | E8: 값
C9: =HOUR(TIME(13,30,45)) | D9: HOUR | E9: 값
C10: =MINUTE(TIME(13,30,45)) | D10: MINUTE | E10: 값
C11: =SECOND(TIME(13,30,45)) | D11: SECOND | E11: 값
A12: 0.75 | C12: =HOUR(A12) | D12: HOUR 소수 일련번호 | E12: 값
C13: =TIMEVALUE("13:30") | D13: TIMEVALUE | E13: 값
C14: =HOUR(DATE(2024,3,15)+0.5) | D14: 날짜+시간 값의 시 | E14: 값
C15: =WEEKDAY(DATE(2024,3,15),2) | D15: WEEKDAY 월요일=1 | E15: 값
C16: =WEEKDAY(DATE(2024,3,15),3) | D16: WEEKDAY 월요일=0 | E16: 값
C17: =WEEKNUM(DATE(2024,3,15)) | D17: WEEKNUM 일요일 시작 | E17: 값
C18: =WEEKNUM(DATE(2024,3,15),2) | D18: WEEKNUM 월요일 시작 | E18: 값
C19: =WEEKNUM(DATE(2024,1,1)) | D19: WEEKNUM 연초 | E19: 값
C20: =_xlfn.ISOWEEKNUM(DATE(2024,3,15)) | D20: ISOWEEKNUM | E20: 값
C21: =_xlfn.ISOWEEKNUM(DATE(2021,1,1)) | D21: ISOWEEKNUM 전년도 주 | E21: 값
C22: =EDATE(DATE(2024,1,31),1) | D22: EDATE 말일: 윤년 2월 29일이어야 함 | E22: 값
C23: =EDATE(DATE(2023,1,31),1) | D23: EDATE 말일: 평년 2월 28일 | E23: 값
C24: =EDATE(DATE(2024,1,15),1) | D24: EDATE | E24: 값
C25: =EDATE(DATE(2024,3,31),-1) | D25: EDATE 음수 개월 | E25: 값
C26: =EDATE(DATE(2024,1,15),12) | D26: EDATE 12개월 | E26: 값
C27: =EOMONTH(DATE(2024,1,15),0) | D27: EOMONTH | E27: 값
C28: =EOMONTH(DATE(2024,1,31),1) | D28: EOMONTH 윤년 2월 | E28: 값
C29: =EOMONTH(DATE(2023,1,31),1) | D29: EOMONTH 평년 2월 | E29: 값
C30: =EOMONTH(DATE(2024,3,15),-1) | D30: EOMONTH 음수 | E30: 값
C31: =NETWORKDAYS(DATE(2024,3,1),DATE(2024,3,15)) | D31: NETWORKDAYS | E31: 값
C32: =NETWORKDAYS(DATE(2024,3,15),DATE(2024,3,1)) | D32: NETWORKDAYS 거꾸로 | E32: 값
C33: =WORKDAY(DATE(2024,3,1),5) | D33: WORKDAY | E33: 값
C34: =WORKDAY(DATE(2024,3,1),-1) | D34: WORKDAY 음수 | E34: 값
C35: =_xlfn.DAYS(DATE(2024,3,15),DATE(2024,3,1)) | D35: DAYS | E35: 값
C36: =_xlfn.DAYS(DATE(2024,3,1),DATE(2024,3,15)) | D36: DAYS 음수 | E36: 값
C37: =DAYS360(DATE(2024,1,31),DATE(2024,3,31)) | D37: DAYS360 | E37: 값
C38: =YEARFRAC(DATE(2024,1,1),DATE(2024,7,1)) | D38: YEARFRAC 기본(30/360) | E38: 값
C39: =YEARFRAC(DATE(2024,1,1),DATE(2024,7,1),1) | D39: YEARFRAC 실제/실제 | E39: 값
C40: =DATEDIF(DATE(2000,5,15),DATE(2024,3,15),"Y") | D40: DATEDIF Y | E40: 값
...

Sheet Lookup
A1: 입력1 | B1: 입력2 | C1: 수식 | D1: 검증 내용 | E1: 비교 방식
C2: =VLOOKUP(85,Data!J2:K6,2,TRUE) | D2: VLOOKUP 근사 일치 | E2: 값
C3: =VLOOKUP(85,Data!J2:K6,2) | D3: VLOOKUP 4번째 인수 생략(근사 일치) | E3: 값
C4: =VLOOKUP(59,Data!J2:K6,2,TRUE) | D4: VLOOKUP 근사: 경계 바로 아래 | E4: 값
C5: =VLOOKUP(60,Data!J2:K6,2,TRUE) | D5: VLOOKUP 근사: 경계 값 | E5: 값
C6: =VLOOKUP(-1,Data!J2:K6,2,TRUE) | D6: VLOOKUP 근사: 첫 값보다 작음 | E6: 값
C7: =VLOOKUP(1000,Data!J2:K6,2,TRUE) | D7: VLOOKUP 근사: 마지막 값보다 큼 | E7: 값
C8: =VLOOKUP("사*",Data!A2:C6,2,FALSE) | D8: VLOOKUP 정확히 일치 + 와일드카드 | E8: 값
C9: =VLOOKUP("사과",Data!A2:C6,0,FALSE) | D9: VLOOKUP 열 번호 0 | E9: 값
C10: =VLOOKUP("SA",Data!A2:C6,2,FALSE) | D10: VLOOKUP 없는 값 | E10: 값
C11: =HLOOKUP("수량",Data!A1:D6,2,FALSE) | D11: HLOOKUP | E11: 값
C12: =HLOOKUP("단가",Data!A1:D6,6,FALSE) | D12: HLOOKUP 마지막 행 | E12: 값
C13: =MATCH(85,Data!J2:J6,1) | D13: MATCH 1 (작거나 같은 최댓값) | E13: 값
C14: =MATCH(85,Data!J2:J6) | D14: MATCH 3번째 인수 생략 | E14: 값
C15: =MATCH(85,Data!M2:M6,-1) | D15: MATCH -1 (내림차순) | E15: 값
C16: =MATCH("사*",Data!A2:A6,0) | D16: MATCH 와일드카드 | E16: 값
C17: =MATCH("사과",Data!A2:A6,0) | D17: MATCH 정확히 일치 | E17: 값
C18: =INDEX(Data!A2:C6,2,3) | D18: INDEX 행·열 | E18: 값
C19: =INDEX(Data!A2:A6,3) | D19: INDEX 한 열 범위 | E19: 값
C20: =INDEX(Data!D2:D6,1) | D20: INDEX 빈 셀(0) | E20: 값
C21: =INDEX(Data!A2:C6,MATCH("귤",Data!A2:A6,0),MATCH("단가",Data!A1:C1,0)) | D21: INDEX+MATCH 양방향 | E21: 값
C22: =_xlfn.XLOOKUP("영업",Data!H2:H7,Data!F2:F7) | D22: XLOOKUP 정확히 일치(처음 값) | E22: 값
C23: =_xlfn.XLOOKUP("없음",Data!H2:H7,Data!F2:F7,"없음") | D23: XLOOKUP 못 찾았을 때 대체 값 | E23: 값
C24: =_xlfn.XLOOKUP("없음",Data!H2:H7,Data!F2:F7) | D24: XLOOKUP 못 찾음 #N/A | E24: 값
C25: =_xlfn.XLOOKUP(85,Data!J2:J6,Data!K2:K6,"없음",-1) | D25: XLOOKUP 작거나 같은 값 | E25: 값
C26: =_xlfn.XLOOKUP(85,Data!J2:J6,Data!K2:K6,"없음",1) | D26: XLOOKUP 크거나 같은 값 | E26: 값
C27: =_xlfn.XLOOKUP(85,Data!J2:J6,Data!K2:K6) | D27: XLOOKUP 정확히 일치만 → #N/A | E27: 값
C28: =_xlfn.XLOOKUP("*",Data!F2:F7,Data!G2:G7,"없음",2) | D28: XLOOKUP 와일드카드 모드 | E28: 값
C29: =_xlfn.XLOOKUP("한*",Data!F2:F7,Data!G2:G7,"없음",2) | D29: XLOOKUP 와일드카드: 문자 값 반환 | E29: 값
C30: =_xlfn.XLOOKUP("영업",Data!H2:H7,Data!F2:F7,,0,-1) | D30: XLOOKUP 마지막부터 검색 | E30: 값
C31: =_xlfn.XLOOKUP(85,Data!J2:J6,Data!K2:K6,"없음",-1,2) | D31: XLOOKUP 이진 검색(오름차순) | E31: 값
C32: =_xlfn.XLOOKUP("점수",Data!F1:H1,Data!F2:H2) | D32: XLOOKUP 가로 방향 | E32: 값
C33: =_xlfn.XLOOKUP("김민준",Data!F2:F7,Data!G2:G7) | D33: XLOOKUP 숫자 반환 | E33: 값
C34: =_xlfn.XLOOKUP("Y",Data!H2:H7,Data!F2:F7,"없음") | D34: XLOOKUP 일부만 같은 값은 못 찾음 | E34: 값
C35: =_xlfn.XLOOKUP(1,Data!A2:A3,Data!B2:B4) | D35: XLOOKUP 범위 크기 불일치 | E35: 값
C36: =_xlfn.XLOOKUP(1/0,Data!H2:H7,Data!F2:F7) | D36: XLOOKUP 찾는 값이 오류 | E36: 값
C37: =_xlfn.IFNA(MATCH(999,Data!B2:B6,0),"없음") | D37: IFNA #N/A 대체 | E37: 값
C38: =_xlfn.IFNA(1/0,"없음") | D38: IFNA는 #N/A만 대체 → #DIV/0! | E38: 값
C39: =SUM(_xlfn._xlws.FILTER(Data!G2:G7,Data!H2:H7="영업")) | D39: FILTER 결과의 합 (문자 무시) | E39: 값
C40: =ROWS(_xlfn._xlws.FILTER(Data!F2:F7,Data!H2:H7="영업")) | D40: FILTER 결과 행 수 | E40: 값
...

Sheet Aggregate
A1: 입력1 | B1: 입력2 | C1: 수식 | D1: 검증 내용 | E1: 비교 방식
C2: =SUM(1,2,3) | D2: SUM 여러 인수 | E2: 값
C3: =SUM(Data!G2:G7,10) | D3: SUM 범위와 상수 | E3: 값
C4: =SUM("3",2) | D4: SUM 숫자 문자열 직접 인수 | E4: 값
C5: =SUM("a",2) | D5: SUM 변환 불가 문자열 직접 인수 | E5: 값
C6: =SUM(TRUE,2) | D6: SUM 논리값 직접 인수 | E6: 값
C7: =AVERAGE(1,"a") | D7: AVERAGE 변환 불가 문자열 | E7: 값
C8: =AVERAGE("3",5) | D8: AVERAGE 숫자 문자열 | E8: 값
C9: =AVERAGE(Data!D2:D2) | D9: AVERAGE 빈 셀만 → #DIV/0! | E9: 값
C10: =MAX(Data!D2:D2) | D10: MAX 빈 셀만 → 0 | E10: 값
C11: =MIN(Data!G5:G5) | D11: MIN 빈 셀만 → 0 | E11: 값
C12: =MAX(Data!G2:G7,100) | D12: MAX 범위와 상수 | E12: 값
C13: =COUNT(1,"a",TRUE,"3") | D13: COUNT 직접 인수 | E13: 값
C14: =COUNT(Data!G2:G7) | D14: COUNT 범위 | E14: 값
C15: =COUNTA("",1) | D15: COUNTA 빈 문자열은 셈 | E15: 값
C16: =COUNTA(Data!G2:G7) | D16: COUNTA 범위 | E16: 값
C17: =COUNTBLANK(Data!G2:G7) | D17: COUNTBLANK | E17: 값
C18: =COUNTIF(Data!G2:G7,"") | D18: COUNTIF 빈 조건 | E18: 값
C19: =COUNTIF(Data!G2:G7,"<>") | D19: COUNTIF 비어 있지 않은 셀 | E19: 값
C20: =COUNTIF(Data!H2:H7,"영*") | D20: COUNTIF 와일드카드 * | E20: 값
C21: =COUNTIF(Data!G2:G7,">=78") | D21: COUNTIF 비교 조건 | E21: 값
C22: =COUNTIF(Data!G2:G7,85) | D22: COUNTIF 숫자 조건 | E22: 값
C23: =COUNTIF(Data!G2:G7,"<>85") | D23: COUNTIF <>숫자 | E23: 값
C24: =COUNTIF(Data!H2:H7,"<>영업") | D24: COUNTIF <>문자 | E24: 값
C25: =COUNTIF(Data!H2:H7,"영업 ") | D25: COUNTIF 끝 공백은 다른 값 | E25: 값
C26: =COUNTIFS(Data!H2:H7,"영*",Data!G2:G7,">=80") | D26: COUNTIFS 와일드카드+비교 | E26: 값
C27: =COUNTIFS(Data!H2:H7,"영업",Data!G2:G7,"<>") | D27: COUNTIFS 비어 있지 않은 셀 | E27: 값
C28: =COUNTIFS(Data!G2:G7,">70",Data!G2:G7,"<90") | D28: COUNTIFS 같은 범위 두 조건 | E28: 값
C29: =SUMIF(Data!G2:G7,">80") | D29: SUMIF 합계 범위 생략 | E29: 값
C30: =SUMIF(Data!H2:H7,"<>영업",Data!G2:G7) | D30: SUMIF <>문자 | E30: 값
C31: =SUMIF(Data!H2:H7,"영*",Data!G2:G7) | D31: SUMIF 와일드카드 | E31: 값
C32: =SUMIFS(Data!G2:G7,Data!H2:H7,"영업",Data!G2:G7,">=80") | D32: SUMIFS | E32: 값
C33: =SUMIFS(Data!G2:G7,Data!H2:H7,"없음") | D33: SUMIFS 일치 없음 → 0 | E33: 값
C34: =SUMIFS(Data!G2:G7,Data!H2:H6,"영업") | D34: SUMIFS 범위 크기 불일치 | E34: 값
C35: =IF(Data!G5="","빈칸","값") | D35: IF 빈 셀 비교 | E35: 값
C36: =IF(FALSE,1) | D36: IF 거짓 값 생략 | E36: 값
C37: =IF(0,"a","b") | D37: IF 숫자 조건 0 | E37: 값
C38: =IF("a",1,2) | D38: IF 문자 조건 → #VALUE! | E38: 값
C39: =IF(1/0,1,2) | D39: IF 오류 조건 | E39: 값
C40: =IF(TRUE,1,1/0) | D40: IF 쓰지 않는 분기의 오류 | E40: 값
...

Sheet DynamicArrays
A1: FILTER 한 열 | B1: FILTER 두 열 원본 | D1: FILTER 일치 없음+대체 값 | E1: FILTER 일치 없음 | F1: FILTER 세 번째 인수(Excel은 if_empty) | G1: FILTER 두 조건 곱 | H1: SORT 오름차순 | I1: SORT 내림차순 | J1: SORT 두 열 기준 열 2 | L1: UNIQUE | M1: UNIQUE 한 번만 나온 값 | N1: UNIQUE 빈 셀 포함 | O1: SORT(UNIQUE()) | P1: SEQUENCE 2x3 | S1: SEQUENCE 시작·증가 | T1: XLOOKUP 여러 열 반환 | V1: TRANSPOSE
A2: {=_xlfn._xlws.FILTER(Data!F2:F7,Data!H2:H7="영업")} | B2: {=_xlfn._xlws.FILTER(Data!F2:G7,Data!H2:H7="영업")} | D2: {=_xlfn._xlws.FILTER(Data!F2:F7,Data!H2:H7="없음","없음")} | E2: {=_xlfn._xlws.FILTER(Data!F2:F7,Data!H2:H7="없음")} | F2: {=_xlfn._xlws.FILTER(Data!F2:F7,Data!H2:H7="영업",Data!G2:G7>80)} | G2: {=_xlfn._xlws.FILTER(Data!F2:F7,(Data!H2:H7="영업")*(Data!G2:G7>80))} | H2: {=_xlfn._xlws.SORT(Data!B2:B6)} | I2: {=_xlfn._xlws.SORT(Data!B2:B6,1,-1)} | J2: {=_xlfn._xlws.SORT(Data!A2:B6,2,-1)} | L2: {=_xlfn.UNIQUE(Data!H2:H7)} | M2: {=_xlfn.UNIQUE(Data!H2:H7,FALSE,TRUE)} | N2: {=_xlfn.UNIQUE(Data!D2:D6)} | O2: {=_xlfn._xlws.SORT(_xlfn.UNIQUE(Data!H2:H7))} | P2: {=_xlfn.SEQUENCE(2,3)} | S2: {=_xlfn.SEQUENCE(3,1,10,5)} | T2: {=_xlfn.XLOOKUP("영업",Data!H2:H7,Data!F2:G7)} | V2: {=TRANSPOSE(Data!F2:F4)}
